(dp1
S'output'
p2
S"<type 'exceptions.AttributeError'> "
p3
sS'layer'
p4
S'C:\\Users\\Ignacio\\Desktop\\CMPS183\\Final_Project\\web2py\\applications\\final_project\\controllers/default.py'
p5
sS'code'
p6
S'<code object <module> at 000000000A8873B0, file "C:\\Users\\Ignacio\\Desktop\\CMPS183\\Final_Project\\web2py\\applications\\final_project\\controllers/default.py", line 9>'
p7
sS'snapshot'
p8
(dp9
sS'traceback'
p10
S'Traceback (most recent call last):\n  File "C:\\Users\\Ignacio\\Desktop\\CMPS183\\Final_Project\\web2py\\gluon\\restricted.py", line 219, in restricted\n    exec(ccode, environment)\n  File "C:\\Users\\Ignacio\\Desktop\\CMPS183\\Final_Project\\web2py\\applications\\final_project\\controllers/default.py", line 116, in <module>\n  File "C:\\Users\\Ignacio\\Desktop\\CMPS183\\Final_Project\\web2py\\gluon\\globals.py", line 421, in <lambda>\n    self._caller = lambda f: f()\n  File "C:\\Users\\Ignacio\\Desktop\\CMPS183\\Final_Project\\web2py\\applications\\final_project\\controllers/default.py", line 43, in profile\n    string = auth.user.mail\n  File "C:\\Users\\Ignacio\\Desktop\\CMPS183\\Final_Project\\web2py\\gluon\\packages\\dal\\pydal\\objects.py", line 118, in __getattr__\n    raise AttributeError\nAttributeError\n'
p11
s.